Workbook

Sheet Summary
A1: CDU Factory Test Report
A6: Work Order Number | B6: WO2601284
A7: Sale Order Number | B7: Enter Sale Order #
A8: Part Number | B8: Enter Part Number
A9: Software Version | B9: 0.23
A10: Firmware Version | B10: 0.23
A11: Serial Number | B11: 1.41.329
A12: Tested by | B12: Luis.Andrade
A13: Date Tested | B13: 2026-09-25
A14: Final Result | B14: =IF(SUM(Decision!B5:AX32)=1372,"Pass","Fail") -> Fail
A17: Active Alarms Test
A18: Active Alarms

Sheet Measurements
A1: Time | B1: Status (0-off 1-on) | C1: Group (0-standalone 1-Group lead 2-Group follow) | D1: TT01 | E1: TT02 | F1: TT31 | G1: TT41 | H1: TT61 | I1: TT62 | J1: TT51 | K1: TT52 | L1: TT45 | M1: PT01 | N1: PT02 | O1: PT31 | P1: PT41 | Q1: PT32 | R1: PT42 | S1: PT21 | T1: PT11 | U1: PT51 | V1: PT52 | W1: PT53 | X1: PT61 | Y1: PT62 | Z1: TT01/TT02 | AA1: TT31/TT41 | AB1: TT61/TT62 | AC1: TT51/TT52 | AD1: PT01/PT02 | AE1: PT32/PT42 | AF1: PT61/PT62 | AG1: PT51/PT52 | AH1: Pump 31 Filter DP | AI1: Pump 41 Filter DP | AJ1: Primary Filter 53 DP | AK1: Secondary DP (Supply - Return) | AL1: Primary DP (Supply - Return) | AM1: FT01 | AN1: FT61 | AO1: P31 Speed % | AP1: P41 Speed % | AQ1: FCV61 Actual Flow% | AR1: FCV61 Actual Open% | AS1: Air Humidity | AT1: Air Temperature | AU1: Program version | AV1: Secondary Temperature Setpoint | AW1: Secondary DP Setpoint | AX1: Secondary Flow Setpoint
A2: sec | B2: [] | C2: [] | D2: C | E2: C | F2: C | G2: C | H2: PSI | I2: PSI | J2: PSI | K2: PSI | L2: PSI | M2: PSI | N2: PSI | O2: PSI | P2: C | Q2: C | R2: PSI | S2: PSI | T2: PSI | U2: PSI | V2: PSI | W2: g/min | X2: % | Y2: % | Z2: % | AA2: % | AB2: % | AC2: % | AD2: % | AE2: C | AF2: [] | AG2: C | AH2: PSI | AI2: g/min | AJ2: PSI | AK2: PSI | AL2: PSI | AM2: FT | AN2: FT | AO2: % | AP2: % | AQ2: % | AR2: % | AS2: % | AT2: C | AU2: [] | AV2: C | AW2: PSI | AX2: g/m
A3: 15 | B3: 1 | C3: 0 | D3: 28.7 | E3: 28.7 | F3: 28.7 | G3: 28.8 | H3: 28.7 | I3: 28.6 | J3: 28.8 | K3: 28.7 | L3: 27.8 | M3: 25.6 | N3: 25.7 | O3: 40.8 | P3: 40.5 | Q3: 38.1 | R3: 38.2 | S3: 19.6 | T3: 0.1 | U3: 38.5 | V3: 38.5 | W3: 36.8 | X3: 28.2 | Y3: 28.4 | Z3: 28.7 | AA3: 28.7 | AB3: 28.7 | AC3: 28.7 | AD3: 25.6 | AE3: 38.1 | AF3: 28.3 | AG3: 38.5 | AH3: 40.6 | AI3: 2.5 | AJ3: 1.7 | AK3: 15 | AL3: 10.3 | AM3: 1410.2 | AN3: 1115.5 | AO3: 6.7 | AP3: 6.8 | AQ3: 10 | AR3: 9.9 | AS3: 49.7 | AT3: 21.8 | AU3: 23 | AV3: 40 | AW3: 15 | AX3: 100
A4: 15 | B4: 1 | C4: 0 | D4: 28.7 | E4: 28.7 | F4: 28.7 | G4: 28.8 | H4: 28.7 | I4: 28.6 | J4: 28.8 | K4: 28.7 | L4: 27.8 | M4: 25.6 | N4: 25.7 | O4: 40.8 | P4: 40.5 | Q4: 38.1 | R4: 38.2 | S4: 19.6 | T4: 0.1 | U4: 38.5 | V4: 38.5 | W4: 36.8 | X4: 28.2 | Y4: 28.4 | Z4: 28.7 | AA4: 28.7 | AB4: 28.7 | AC4: 28.7 | AD4: 25.6 | AE4: 38.1 | AF4: 28.3 | AG4: 38.5 | AH4: 40.6 | AI4: 2.5 | AJ4: 1.7 | AK4: 15 | AL4: 10.3 | AM4: 1410.2 | AN4: 1115.5 | AO4: 6.7 | AP4: 6.8 | AQ4: 10 | AR4: 9.9 | AS4: 49.7 | AT4: 21.8 | AU4: 23 | AV4: 21 | AW4: 15 | AX4: 100
A5: 15 | B5: 1 | C5: 0 | D5: 28.7 | E5: 28.7 | F5: 28.7 | G5: 28.8 | H5: 28.7 | I5: 28.6 | J5: 28.8 | K5: 28.7 | L5: 27.8 | M5: 25.6 | N5: 25.7 | O5: 40.8 | P5: 40.5 | Q5: 38.1 | R5: 38.2 | S5: 19.6 | T5: 0.1 | U5: 38.5 | V5: 38.5 | W5: 36.8 | X5: 28.2 | Y5: 28.4 | Z5: 28.7 | AA5: 28.7 | AB5: 28.7 | AC5: 28.7 | AD5: 25.6 | AE5: 38.1 | AF5: 28.3 | AG5: 38.5 | AH5: 40.6 | AI5: 2.5 | AJ5: 1.7 | AK5: 15 | AL5: 10.3 | AM5: 1410.2 | AN5: 1115.5 | AO5: 6.7 | AP5: 6.8 | AQ5: 10 | AR5: 9.9 | AS5: 49.7 | AT5: 21.8 | AU5: 23 | AV5: 21 | AW5: 5 | AX5: 100
A6: 75 | B6: 1 | C6: 0 | D6: 28.8 | E6: 28.8 | F6: 28.8 | G6: 28.9 | H6: 28.8 | I6: 28.7 | J6: 28.8 | K6: 28.8 | L6: 27.9 | M6: 26.1 | N6: 26.3 | O6: 36.9 | P6: 36.4 | Q6: 34.6 | R6: 34.6 | S6: 21.5 | T6: 0.1 | U6: 35.6 | V6: 35.5 | W6: 34.1 | X6: 28.1 | Y6: 28.3 | Z6: 28.8 | AA6: 28.8 | AB6: 28.8 | AC6: 28.8 | AD6: 26.2 | AE6: 34.6 | AF6: 28.2 | AG6: 35.5 | AH6: 36.7 | AI6: 2.1 | AJ6: 1.5 | AK6: 10.9 | AL6: 7.3 | AM6: 1285.1 | AN6: 1001.9 | AO6: 5.7 | AP6: 5.7 | AQ6: 10 | AR6: 9.9 | AS6: 49.9 | AT6: 21.7 | AU6: 23 | AV6: 21 | AW6: 5 | AX6: 160
A7: 75 | B7: 1 | C7: 0 | D7: 28.8 | E7: 28.8 | F7: 28.8 | G7: 28.9 | H7: 28.8 | I7: 28.7 | J7: 28.8 | K7: 28.8 | L7: 27.9 | M7: 26.1 | N7: 26.3 | O7: 36.9 | P7: 36.4 | Q7: 34.6 | R7: 34.6 | S7: 21.5 | T7: 0.1 | U7: 35.6 | V7: 35.5 | W7: 34.1 | X7: 28.1 | Y7: 28.3 | Z7: 28.8 | AA7: 28.8 | AB7: 28.8 | AC7: 28.8 | AD7: 26.2 | AE7: 34.6 | AF7: 28.2 | AG7: 35.5 | AH7: 36.7 | AI7: 2.1 | AJ7: 1.5 | AK7: 10.9 | AL7: 7.3 | AM7: 1285.1 | AN7: 1001.9 | AO7: 5.7 | AP7: 5.7 | AQ7: 10 | AR7: 9.9 | AS7: 49.9 | AT7: 21.7 | AU7: 23 | AV7: 21 | AW7: 5 | AX7: 160
A8: 75 | B8: 1 | C8: 0 | D8: 28.8 | E8: 28.8 | F8: 28.8 | G8: 28.9 | H8: 28.8 | I8: 28.7 | J8: 28.8 | K8: 28.8 | L8: 27.9 | M8: 26.1 | N8: 26.3 | O8: 36.8 | P8: 36.4 | Q8: 34.4 | R8: 34.5 | S8: 21.5 | T8: 0.1 | U8: 35.5 | V8: 35.5 | W8: 34 | X8: 28.1 | Y8: 28.3 | Z8: 28.8 | AA8: 28.8 | AB8: 28.8 | AC8: 28.8 | AD8: 26.2 | AE8: 34.4 | AF8: 28.2 | AG8: 35.5 | AH8: 36.6 | AI8: 2.2 | AJ8: 1.5 | AK8: 10.8 | AL8: 7.3 | AM8: 1285.1 | AN8: 999.1 | AO8: 5.7 | AP8: 5.7 | AQ8: 10 | AR8: 9.9 | AS8: 49.9 | AT8: 21.7 | AU8: 23 | AV8: 21 | AW8: 10 | AX8: 160
A9: 135 | B9: 1 | C9: 0 | D9: 28.9 | E9: 28.9 | F9: 28.9 | G9: 28.9 | H9: 28.9 | I9: 28.8 | J9: 28.9 | K9: 28.9 | L9: 28 | M9: 26.1 | N9: 26.3 | O9: 36.8 | P9: 36.4 | Q9: 34.5 | R9: 34.5 | S9: 21.5 | T9: 0.1 | U9: 35.4 | V9: 35.5 | W9: 34 | X9: 28.1 | Y9: 28.3 | Z9: 28.9 | AA9: 28.9 | AB9: 28.9 | AC9: 28.9 | AD9: 26.2 | AE9: 34.5 | AF9: 28.2 | AG9: 35.4 | AH9: 36.6 | AI9: 2.1 | AJ9: 1.4 | AK9: 10.8 | AL9: 7.3 | AM9: 1283.7 | AN9: 990.4 | AO9: 5.7 | AP9: 5.7 | AQ9: 10 | AR9: 9.9 | AS9: 50.1 | AT9: 21.7 | AU9: 23 | AV9: 21 | AW9: 10 | AX9: 320
A10: 135 | B10: 1 | C10: 0 | D10: 28.9 | E10: 28.9 | F10: 28.9 | G10: 28.9 | H10: 28.9 | I10: 28.8 | J10: 28.9 | K10: 28.9 | L10: 28 | M10: 26.1 | N10: 26.3 | O10: 36.8 | P10: 36.4 | Q10: 34.5 | R10: 34.5 | S10: 21.5 | T10: 0.1 | U10: 35.4 | V10: 35.5 | W10: 34 | X10: 28.1 | Y10: 28.3 | Z10: 28.9 | AA10: 28.9 | AB10: 28.9 | AC10: 28.9 | AD10: 26.2 | AE10: 34.5 | AF10: 28.2 | AG10: 35.4 | AH10: 36.6 | AI10: 2.1 | AJ10: 1.4 | AK10: 10.8 | AL10: 7.3 | AM10: 1283.7 | AN10: 990.4 | AO10: 5.7 | AP10: 5.7 | AQ10: 10 | AR10: 9.9 | AS10: 50.1 | AT10: 21.7 | AU10: 23 | AV10: 22 | AW10: 10 | AX10: 320
A11: 135 | B11: 1 | C11: 0 | D11: 28.9 | E11: 28.9 | F11: 28.9 | G11: 28.9 | H11: 28.9 | I11: 28.8 | J11: 28.9 | K11: 28.9 | L11: 28 | M11: 26.1 | N11: 26.3 | O11: 36.8 | P11: 36.4 | Q11: 34.5 | R11: 34.5 | S11: 21.5 | T11: 0.1 | U11: 35.4 | V11: 35.5 | W11: 34 | X11: 28.1 | Y11: 28.3 | Z11: 28.9 | AA11: 28.9 | AB11: 28.9 | AC11: 28.9 | AD11: 26.2 | AE11: 34.5 | AF11: 28.2 | AG11: 35.4 | AH11: 36.6 | AI11: 2.1 | AJ11: 1.4 | AK11: 10.8 | AL11: 7.3 | AM11: 1283.7 | AN11: 990.4 | AO11: 5.7 | AP11: 5.7 | AQ11: 10 | AR11: 9.9 | AS11: 50.1 | AT11: 21.7 | AU11: 23 | AV11: 22 | AW11: 25 | AX11: 320
A12: 195 | B12: 1 | C12: 0 | D12: 29.1 | E12: 29.1 | F12: 29.2 | G12: 29.2 | H12: 29.2 | I12: 29.1 | J12: 29.2 | K12: 29.2 | L12: 28.1 | M12: 24.9 | N12: 25 | O12: 50 | P12: 49.8 | Q12: 46.7 | R12: 46.9 | S12: 16.1 | T12: 0.1 | U12: 46 | V12: 46 | W12: 43.7 | X12: 29.8 | Y12: 29.8 | Z12: 29.1 | AA12: 29.2 | AB12: 29.1 | AC12: 29.2 | AD12: 24.9 | AE12: 46.8 | AF12: 29.8 | AG12: 46 | AH12: 49.9 | AI12: 3.1 | AJ12: 2.3 | AK12: 24.4 | AL12: 16.2 | AM12: 1750.9 | AN12: 1469.1 | AO12: 8.5 | AP12: 8.5 | AQ12: 10 | AR12: 9.9 | AS12: 50.5 | AT12: 21.7 | AU12: 23 | AV12: 22 | AW12: 25 | AX12: 480
A13: 195 | B13: 1 | C13: 0 | D13: 29.1 | E13: 29.1 | F13: 29.2 | G13: 29.2 | H13: 29.2 | I13: 29.1 | J13: 29.2 | K13: 29.2 | L13: 28.1 | M13: 24.9 | N13: 25 | O13: 50 | P13: 49.8 | Q13: 46.7 | R13: 46.9 | S13: 16.1 | T13: 0.1 | U13: 46 | V13: 46 | W13: 43.7 | X13: 29.8 | Y13: 29.8 | Z13: 29.1 | AA13: 29.2 | AB13: 29.1 | AC13: 29.2 | AD13: 24.9 | AE13: 46.8 | AF13: 29.8 | AG13: 46 | AH13: 49.9 | AI13: 3.1 | AJ13: 2.3 | AK13: 24.4 | AL13: 16.2 | AM13: 1750.9 | AN13: 1469.1 | AO13: 8.5 | AP13: 8.5 | AQ13: 10 | AR13: 9.9 | AS13: 50.5 | AT13: 21.7 | AU13: 23 | AV13: 23 | AW13: 25 | AX13: 480
A14: 195 | B14: 1 | C14: 0 | D14: 29.1 | E14: 29.1 | F14: 29.2 | G14: 29.2 | H14: 29.2 | I14: 29.1 | J14: 29.2 | K14: 29.2 | L14: 28.1 | M14: 24.9 | N14: 25 | O14: 50 | P14: 49.8 | Q14: 46.7 | R14: 46.9 | S14: 16.1 | T14: 0.1 | U14: 46 | V14: 46 | W14: 43.7 | X14: 29.8 | Y14: 29.8 | Z14: 29.1 | AA14: 29.2 | AB14: 29.1 | AC14: 29.2 | AD14: 24.9 | AE14: 46.8 | AF14: 29.8 | AG14: 46 | AH14: 49.9 | AI14: 3.1 | AJ14: 2.3 | AK14: 24.4 | AL14: 16.2 | AM14: 1750.9 | AN14: 1469.1 | AO14: 8.5 | AP14: 8.5 | AQ14: 10 | AR14: 9.9 | AS14: 50.5 | AT14: 21.7 | AU14: 23 | AV14: 23 | AW14: 33 | AX14: 480
... A32: 525 | B32: 1 | C32: 0 | D32: 31.1 | E32: 31.1 | F32: 31.1 | G32: 31.2 | H32: 31.1 | I32: 31 | J32: 31.2 | K32: 31.1 | L32: 29.7 | M32: 26.4 | N32: 26.5 | O32: 37.1 | P32: 36.7 | Q32: 34.6 | R32: 34.7 | S32: 22.1 | T32: 0 | U32: 35.7 | V32: 35.7 | W32: 34.3 | X32: 28.4 | Y32: 28.6 | Z32: 31.1 | AA32: 31.1 | AB32: 31.1 | AC32: 31.1 | AD32: 26.5 | AE32: 34.7 | AF32: 28.5 | AG32: 35.7 | AH32: 36.9 | AI32: 2.2 | AJ32: 1.4 | AK32: 10.7 | AL32: 7.2 | AM32: 1292.3 | AN32: 1022.1 | AO32: 5.9 | AP32: 5.9 | AQ32: 10 | AR32: 9.9 | AS32: 51.4 | AT32: 21.5 | AU32: 23 | AV32: 27 | AW32: 5 | AX32: 160

Sheet Decision
A1: Time | B1: Status (0-off 1-on) | C1: Group (0-standalone 1-Group lead 2-Group follow) | D1: TT01 | E1: TT02 | F1: TT31 | G1: TT41 | H1: TT61 | I1: TT62 | J1: TT51 | K1: TT52 | L1: TT45 | M1: PT01 | N1: PT02 | O1: PT31 | P1: PT41 | Q1: PT32 | R1: PT42 | S1: PT21 | T1: PT11 | U1: PT51 | V1: PT52 | W1: PT53 | X1: PT61 | Y1: PT62 | Z1: TT01/TT02 | AA1: TT31/TT41 | AB1: TT61/TT62 | AC1: TT51/TT52 | AD1: PT01/PT02 | AE1: PT32/PT42 | AF1: PT61/PT62 | AG1: PT51/PT52 | AH1: Pump 31 Filter DP | AI1: Pump 41 Filter DP | AJ1: Primary Filter 53 DP | AK1: Secondary DP (Supply - Return) | AL1: Primary DP (Supply - Return) | AM1: FT01 | AN1: FT61 | AO1: P31 Speed % | AP1: P41 Speed % | AQ1: FCV61 Actual Flow% | AR1: FCV61 Actual Open% | AS1: Air Humidity | AT1: Air Temperature | AU1: Program version | AV1: Secondary Temperature Setpoint | AW1: Secondary DP Setpoint | AX1: Secondary Flow Setpoint
A2: sec | B2: [] | C2: [] | D2: C | E2: C | F2: C | G2: C | H2: PSI | I2: PSI | J2: PSI | K2: PSI | L2: PSI | M2: PSI | N2: PSI | O2: PSI | P2: C | Q2: C | R2: PSI | S2: PSI | T2: PSI | U2: PSI | V2: PSI | W2: g/min | X2: % | Y2: % | Z2: % | AA2: % | AB2: % | AC2: % | AD2: % | AE2: C | AF2: [] | AG2: C | AH2: PSI | AI2: g/min | AJ2: PSI | AK2: PSI | AL2: PSI | AM2: FT | AN2: FT | AO2: % | AP2: % | AQ2: % | AR2: % | AS2: % | AT2: C | AU2: [] | AV2: C | AW2: PSI | AX2: g/m
A3: 15 | B3: =--AND(Measurements!B3>='mean-3Sigma'!B2, Measurements!B3<='mean+3Sigma'!B2) -> 1 | C3: =--AND(Measurements!C3>='mean-3Sigma'!C2, Measurements!C3<='mean+3Sigma'!C2) -> 1 | D3: =--AND(Measurements!D3>='mean-3Sigma'!D2, Measurements!D3<='mean+3Sigma'!D2) -> 1 | E3: =--AND(Measurements!E3>='mean-3Sigma'!E2, Measurements!E3<='mean+3Sigma'!E2) -> 1 | F3: =--AND(Measurements!F3>='mean-3Sigma'!F2, Measurements!F3<='mean+3Sigma'!F2) -> 1 | G3: =--AND(Measurements!G3>='mean-3Sigma'!G2, Measurements!G3<='mean+3Sigma'!G2) -> 1 | H3: =--AND(Measurements!H3>='mean-3Sigma'!H2, Measurements!H3<='mean+3Sigma'!H2) -> 1 | I3: =--AND(Measurements!I3>='mean-3Sigma'!I2, Measurements!I3<='mean+3Sigma'!I2) -> 1 | ... AX3: =--AND(Measurements!AX3>='mean-3Sigma'!AX2, Measurements!AX3<='mean+3Sigma'!AX2) -> 1
A4: 15 | B4: =--AND(Measurements!B4>='mean-3Sigma'!B3, Measurements!B4<='mean+3Sigma'!B3) -> 1 | C4: =--AND(Measurements!C4>='mean-3Sigma'!C3, Measurements!C4<='mean+3Sigma'!C3) -> 1 | D4: =--AND(Measurements!D4>='mean-3Sigma'!D3, Measurements!D4<='mean+3Sigma'!D3) -> 1 | E4: =--AND(Measurements!E4>='mean-3Sigma'!E3, Measurements!E4<='mean+3Sigma'!E3) -> 1 | F4: =--AND(Measurements!F4>='mean-3Sigma'!F3, Measurements!F4<='mean+3Sigma'!F3) -> 1 | G4: =--AND(Measurements!G4>='mean-3Sigma'!G3, Measurements!G4<='mean+3Sigma'!G3) -> 1 | H4: =--AND(Measurements!H4>='mean-3Sigma'!H3, Measurements!H4<='mean+3Sigma'!H3) -> 1 | I4: =--AND(Measurements!I4>='mean-3Sigma'!I3, Measurements!I4<='mean+3Sigma'!I3) -> 1 | ... AX4: =--AND(Measurements!AX4>='mean-3Sigma'!AX3, Measurements!AX4<='mean+3Sigma'!AX3) -> 0
A5: 15 | B5: =--AND(Measurements!B5>='mean-3Sigma'!B2, Measurements!B5<='mean+3Sigma'!B2) -> 1 | C5: =--AND(Measurements!C5>='mean-3Sigma'!C2, Measurements!C5<='mean+3Sigma'!C2) -> 1 | D5: =--AND(Measurements!D5>='mean-3Sigma'!D2, Measurements!D5<='mean+3Sigma'!D2) -> 1 | E5: =--AND(Measurements!E5>='mean-3Sigma'!E2, Measurements!E5<='mean+3Sigma'!E2) -> 1 | F5: =--AND(Measurements!F5>='mean-3Sigma'!F2, Measurements!F5<='mean+3Sigma'!F2) -> 1 | G5: =--AND(Measurements!G5>='mean-3Sigma'!G2, Measurements!G5<='mean+3Sigma'!G2) -> 1 | H5: =--AND(Measurements!H5>='mean-3Sigma'!H2, Measurements!H5<='mean+3Sigma'!H2) -> 1 | I5: =--AND(Measurements!I5>='mean-3Sigma'!I2, Measurements!I5<='mean+3Sigma'!I2) -> 1 | ... AX5: =--AND(Measurements!AX5>='mean-3Sigma'!AX2, Measurements!AX5<='mean+3Sigma'!AX2) -> 1
A6: 75 | B6: =--AND(Measurements!B6>='mean-3Sigma'!B3, Measurements!B6<='mean+3Sigma'!B3) -> 1 | C6: =--AND(Measurements!C6>='mean-3Sigma'!C3, Measurements!C6<='mean+3Sigma'!C3) -> 1 | D6: =--AND(Measurements!D6>='mean-3Sigma'!D3, Measurements!D6<='mean+3Sigma'!D3) -> 1 | E6: =--AND(Measurements!E6>='mean-3Sigma'!E3, Measurements!E6<='mean+3Sigma'!E3) -> 1 | F6: =--AND(Measurements!F6>='mean-3Sigma'!F3, Measurements!F6<='mean+3Sigma'!F3) -> 1 | G6: =--AND(Measurements!G6>='mean-3Sigma'!G3, Measurements!G6<='mean+3Sigma'!G3) -> 1 | H6: =--AND(Measurements!H6>='mean-3Sigma'!H3, Measurements!H6<='mean+3Sigma'!H3) -> 1 | I6: =--AND(Measurements!I6>='mean-3Sigma'!I3, Measurements!I6<='mean+3Sigma'!I3) -> 1 | ... AX6: =--AND(Measurements!AX6>='mean-3Sigma'!AX3, Measurements!AX6<='mean+3Sigma'!AX3) -> 1
A7: 75 | B7: =--AND(Measurements!B7>='mean-3Sigma'!B4, Measurements!B7<='mean+3Sigma'!B4) -> 1 | C7: =--AND(Measurements!C7>='mean-3Sigma'!C4, Measurements!C7<='mean+3Sigma'!C4) -> 1 | D7: =--AND(Measurements!D7>='mean-3Sigma'!D4, Measurements!D7<='mean+3Sigma'!D4) -> 1 | E7: =--AND(Measurements!E7>='mean-3Sigma'!E4, Measurements!E7<='mean+3Sigma'!E4) -> 1 | F7: =--AND(Measurements!F7>='mean-3Sigma'!F4, Measurements!F7<='mean+3Sigma'!F4) -> 1 | G7: =--AND(Measurements!G7>='mean-3Sigma'!G4, Measurements!G7<='mean+3Sigma'!G4) -> 1 | H7: =--AND(Measurements!H7>='mean-3Sigma'!H4, Measurements!H7<='mean+3Sigma'!H4) -> 1 | I7: =--AND(Measurements!I7>='mean-3Sigma'!I4, Measurements!I7<='mean+3Sigma'!I4) -> 1 | ... AX7: =--AND(Measurements!AX7>='mean-3Sigma'!AX4, Measurements!AX7<='mean+3Sigma'!AX4) -> 1
A8: 75 | B8: =--AND(Measurements!B8>='mean-3Sigma'!B5, Measurements!B8<='mean+3Sigma'!B5) -> 1 | C8: =--AND(Measurements!C8>='mean-3Sigma'!C5, Measurements!C8<='mean+3Sigma'!C5) -> 1 | D8: =--AND(Measurements!D8>='mean-3Sigma'!D5, Measurements!D8<='mean+3Sigma'!D5) -> 1 | E8: =--AND(Measurements!E8>='mean-3Sigma'!E5, Measurements!E8<='mean+3Sigma'!E5) -> 1 | F8: =--AND(Measurements!F8>='mean-3Sigma'!F5, Measurements!F8<='mean+3Sigma'!F5) -> 1 | G8: =--AND(Measurements!G8>='mean-3Sigma'!G5, Measurements!G8<='mean+3Sigma'!G5) -> 1 | H8: =--AND(Measurements!H8>='mean-3Sigma'!H5, Measurements!H8<='mean+3Sigma'!H5) -> 1 | I8: =--AND(Measurements!I8>='mean-3Sigma'!I5, Measurements!I8<='mean+3Sigma'!I5) -> 1 | ... AX8: =--AND(Measurements!AX8>='mean-3Sigma'!AX5, Measurements!AX8<='mean+3Sigma'!AX5) -> 1
A9: 135 | B9: =--AND(Measurements!B9>='mean-3Sigma'!B6, Measurements!B9<='mean+3Sigma'!B6) -> 1 | C9: =--AND(Measurements!C9>='mean-3Sigma'!C6, Measurements!C9<='mean+3Sigma'!C6) -> 1 | D9: =--AND(Measurements!D9>='mean-3Sigma'!D6, Measurements!D9<='mean+3Sigma'!D6) -> 1 | E9: =--AND(Measurements!E9>='mean-3Sigma'!E6, Measurements!E9<='mean+3Sigma'!E6) -> 1 | F9: =--AND(Measurements!F9>='mean-3Sigma'!F6, Measurements!F9<='mean+3Sigma'!F6) -> 1 | G9: =--AND(Measurements!G9>='mean-3Sigma'!G6, Measurements!G9<='mean+3Sigma'!G6) -> 1 | H9: =--AND(Measurements!H9>='mean-3Sigma'!H6, Measurements!H9<='mean+3Sigma'!H6) -> 1 | I9: =--AND(Measurements!I9>='mean-3Sigma'!I6, Measurements!I9<='mean+3Sigma'!I6) -> 1 | ... AX9: =--AND(Measurements!AX9>='mean-3Sigma'!AX6, Measurements!AX9<='mean+3Sigma'!AX6) -> 1
A10: 135 | B10: =--AND(Measurements!B10>='mean-3Sigma'!B7, Measurements!B10<='mean+3Sigma'!B7) -> 1 | C10: =--AND(Measurements!C10>='mean-3Sigma'!C7, Measurements!C10<='mean+3Sigma'!C7) -> 1 | D10: =--AND(Measurements!D10>='mean-3Sigma'!D7, Measurements!D10<='mean+3Sigma'!D7) -> 1 | E10: =--AND(Measurements!E10>='mean-3Sigma'!E7, Measurements!E10<='mean+3Sigma'!E7) -> 1 | F10: =--AND(Measurements!F10>='mean-3Sigma'!F7, Measurements!F10<='mean+3Sigma'!F7) -> 1 | G10: =--AND(Measurements!G10>='mean-3Sigma'!G7, Measurements!G10<='mean+3Sigma'!G7) -> 1 | H10: =--AND(Measurements!H10>='mean-3Sigma'!H7, Measurements!H10<='mean+3Sigma'!H7) -> 1 | I10: =--AND(Measurements!I10>='mean-3Sigma'!I7, Measurements!I10<='mean+3Sigma'!I7) -> 1 | ... AX10: =--AND(Measurements!AX10>='mean-3Sigma'!AX7, Measurements!AX10<='mean+3Sigma'!AX7) -> 1
A11: 135 | B11: =--AND(Measurements!B11>='mean-3Sigma'!B8, Measurements!B11<='mean+3Sigma'!B8) -> 1 | C11: =--AND(Measurements!C11>='mean-3Sigma'!C8, Measurements!C11<='mean+3Sigma'!C8) -> 1 | D11: =--AND(Measurements!D11>='mean-3Sigma'!D8, Measurements!D11<='mean+3Sigma'!D8) -> 1 | E11: =--AND(Measurements!E11>='mean-3Sigma'!E8, Measurements!E11<='mean+3Sigma'!E8) -> 1 | F11: =--AND(Measurements!F11>='mean-3Sigma'!F8, Measurements!F11<='mean+3Sigma'!F8) -> 1 | G11: =--AND(Measurements!G11>='mean-3Sigma'!G8, Measurements!G11<='mean+3Sigma'!G8) -> 1 | H11: =--AND(Measurements!H11>='mean-3Sigma'!H8, Measurements!H11<='mean+3Sigma'!H8) -> 1 | I11: =--AND(Measurements!I11>='mean-3Sigma'!I8, Measurements!I11<='mean+3Sigma'!I8) -> 1 | ... AX11: =--AND(Measurements!AX11>='mean-3Sigma'!AX8, Measurements!AX11<='mean+3Sigma'!AX8) -> 1
A12: 195 | B12: =--AND(Measurements!B12>='mean-3Sigma'!B9, Measurements!B12<='mean+3Sigma'!B9) -> 1 | C12: =--AND(Measurements!C12>='mean-3Sigma'!C9, Measurements!C12<='mean+3Sigma'!C9) -> 1 | D12: =--AND(Measurements!D12>='mean-3Sigma'!D9, Measurements!D12<='mean+3Sigma'!D9) -> 1 | E12: =--AND(Measurements!E12>='mean-3Sigma'!E9, Measurements!E12<='mean+3Sigma'!E9) -> 1 | F12: =--AND(Measurements!F12>='mean-3Sigma'!F9, Measurements!F12<='mean+3Sigma'!F9) -> 1 | G12: =--AND(Measurements!G12>='mean-3Sigma'!G9, Measurements!G12<='mean+3Sigma'!G9) -> 1 | H12: =--AND(Measurements!H12>='mean-3Sigma'!H9, Measurements!H12<='mean+3Sigma'!H9) -> 1 | I12: =--AND(Measurements!I12>='mean-3Sigma'!I9, Measurements!I12<='mean+3Sigma'!I9) -> 1 | ... AX12: =--AND(Measurements!AX12>='mean-3Sigma'!AX9, Measurements!AX12<='mean+3Sigma'!AX9) -> 1
A13: 195 | B13: =--AND(Measurements!B13>='mean-3Sigma'!B10, Measurements!B13<='mean+3Sigma'!B10) -> 1 | C13: =--AND(Measurements!C13>='mean-3Sigma'!C10, Measurements!C13<='mean+3Sigma'!C10) -> 1 | D13: =--AND(Measurements!D13>='mean-3Sigma'!D10, Measurements!D13<='mean+3Sigma'!D10) -> 1 | E13: =--AND(Measurements!E13>='mean-3Sigma'!E10, Measurements!E13<='mean+3Sigma'!E10) -> 1 | F13: =--AND(Measurements!F13>='mean-3Sigma'!F10, Measurements!F13<='mean+3Sigma'!F10) -> 1 | G13: =--AND(Measurements!G13>='mean-3Sigma'!G10, Measurements!G13<='mean+3Sigma'!G10) -> 1 | H13: =--AND(Measurements!H13>='mean-3Sigma'!H10, Measurements!H13<='mean+3Sigma'!H10) -> 1 | I13: =--AND(Measurements!I13>='mean-3Sigma'!I10, Measurements!I13<='mean+3Sigma'!I10) -> 1 | ... AX13: =--AND(Measurements!AX13>='mean-3Sigma'!AX10, Measurements!AX13<='mean+3Sigma'!AX10) -> 1
A14: 195 | B14: =--AND(Measurements!B14>='mean-3Sigma'!B11, Measurements!B14<='mean+3Sigma'!B11) -> 1 | C14: =--AND(Measurements!C14>='mean-3Sigma'!C11, Measurements!C14<='mean+3Sigma'!C11) -> 1 | D14: =--AND(Measurements!D14>='mean-3Sigma'!D11, Measurements!D14<='mean+3Sigma'!D11) -> 1 | E14: =--AND(Measurements!E14>='mean-3Sigma'!E11, Measurements!E14<='mean+3Sigma'!E11) -> 1 | F14: =--AND(Measurements!F14>='mean-3Sigma'!F11, Measurements!F14<='mean+3Sigma'!F11) -> 1 | G14: =--AND(Measurements!G14>='mean-3Sigma'!G11, Measurements!G14<='mean+3Sigma'!G11) -> 1 | H14: =--AND(Measurements!H14>='mean-3Sigma'!H11, Measurements!H14<='mean+3Sigma'!H11) -> 1 | I14: =--AND(Measurements!I14>='mean-3Sigma'!I11, Measurements!I14<='mean+3Sigma'!I11) -> 1 | ... AX14: =--AND(Measurements!AX14>='mean-3Sigma'!AX11, Measurements!AX14<='mean+3Sigma'!AX11) -> 1
A15: 255 | B15: =--AND(Measurements!B15>='mean-3Sigma'!B12, Measurements!B15<='mean+3Sigma'!B12) -> 1 | C15: =--AND(Measurements!C15>='mean-3Sigma'!C12, Measurements!C15<='mean+3Sigma'!C12) -> 1 | D15: =--AND(Measurements!D15>='mean-3Sigma'!D12, Measurements!D15<='mean+3Sigma'!D12) -> 1 | E15: =--AND(Measurements!E15>='mean-3Sigma'!E12, Measurements!E15<='mean+3Sigma'!E12) -> 1 | F15: =--AND(Measurements!F15>='mean-3Sigma'!F12, Measurements!F15<='mean+3Sigma'!F12) -> 1 | G15: =--AND(Measurements!G15>='mean-3Sigma'!G12, Measurements!G15<='mean+3Sigma'!G12) -> 1 | H15: =--AND(Measurements!H15>='mean-3Sigma'!H12, Measurements!H15<='mean+3Sigma'!H12) -> 1 | I15: =--AND(Measurements!I15>='mean-3Sigma'!I12, Measurements!I15<='mean+3Sigma'!I12) -> 1 | ... AX15: =--AND(Measurements!AX15>='mean-3Sigma'!AX12, Measurements!AX15<='mean+3Sigma'!AX12) -> 1
A16: 255 | B16: =--AND(Measurements!B16>='mean-3Sigma'!B13, Measurements!B16<='mean+3Sigma'!B13) -> 1 | C16: =--AND(Measurements!C16>='mean-3Sigma'!C13, Measurements!C16<='mean+3Sigma'!C13) -> 1 | D16: =--AND(Measurements!D16>='mean-3Sigma'!D13, Measurements!D16<='mean+3Sigma'!D13) -> 1 | E16: =--AND(Measurements!E16>='mean-3Sigma'!E13, Measurements!E16<='mean+3Sigma'!E13) -> 1 | F16: =--AND(Measurements!F16>='mean-3Sigma'!F13, Measurements!F16<='mean+3Sigma'!F13) -> 1 | G16: =--AND(Measurements!G16>='mean-3Sigma'!G13, Measurements!G16<='mean+3Sigma'!G13) -> 1 | H16: =--AND(Measurements!H16>='mean-3Sigma'!H13, Measurements!H16<='mean+3Sigma'!H13) -> 1 | I16: =--AND(Measurements!I16>='mean-3Sigma'!I13, Measurements!I16<='mean+3Sigma'!I13) -> 1 | ... AX16: =--AND(Measurements!AX16>='mean-3Sigma'!AX13, Measurements!AX16<='mean+3Sigma'!AX13) -> 1
... A32: 525 | B32: =--AND(Measurements!B32>='mean-3Sigma'!B29, Measurements!B32<='mean+3Sigma'!B29) -> 1 | C32: =--AND(Measurements!C32>='mean-3Sigma'!C29, Measurements!C32<='mean+3Sigma'!C29) -> 1 | D32: =--AND(Measurements!D32>='mean-3Sigma'!D29, Measurements!D32<='mean+3Sigma'!D29) -> 1 | E32: =--AND(Measurements!E32>='mean-3Sigma'!E29, Measurements!E32<='mean+3Sigma'!E29) -> 1 | F32: =--AND(Measurements!F32>='mean-3Sigma'!F29, Measurements!F32<='mean+3Sigma'!F29) -> 1 | G32: =--AND(Measurements!G32>='mean-3Sigma'!G29, Measurements!G32<='mean+3Sigma'!G29) -> 1 | H32: =--AND(Measurements!H32>='mean-3Sigma'!H29, Measurements!H32<='mean+3Sigma'!H29) -> 1 | I32: =--AND(Measurements!I32>='mean-3Sigma'!I29, Measurements!I32<='mean+3Sigma'!I29) -> 1 | ... AX32: =--AND(Measurements!AX32>='mean-3Sigma'!AX29, Measurements!AX32<='mean+3Sigma'!AX29) -> 1

Sheet Description of Diagnostics

Sheet mean-3Sigma
A1: Time | B1: Status (0-off 1-on) | C1: Group (0-standalone 1-Group lead 2-Group follow) | D1: TT01 | E1: TT02 | F1: TT31 | G1: TT41 | H1: TT61 | I1: TT62 | J1: TT51 | K1: TT52 | L1: TT45 | M1: PT01 | N1: PT02 | O1: PT31 | P1: PT41 | Q1: PT32 | R1: PT42 | S1: PT21 | T1: PT11 | U1: PT51 | V1: PT52 | W1: PT53 | X1: PT61 | Y1: PT62 | Z1: TT01/TT02 | AA1: TT31/TT41 | AB1: TT61/TT62 | AC1: TT51/TT52 | AD1: PT01/PT02 | AE1: PT32/PT42 | AF1: PT61/PT62 | AG1: PT51/PT52 | AH1: Pump 31 Filter DP | AI1: Pump 41 Filter DP | AJ1: Primary Filter 53 DP | AK1: Secondary DP (Supply - Return) | AL1: Primary DP (Supply - Return) | AM1: FT01 | AN1: FT61 | AO1: P31 Speed % | AP1: P41 Speed % | AQ1: FCV61 Actual Flow% | AR1: FCV61 Actual Open% | AS1: Air Humidity | AT1: Air Temperature | AU1: Program version | AV1: Secondary Temperature Setpoint | AW1: Secondary DP Setpoint | AX1: Secondary Flow Setpoint
A2: 15 | B2: 1 | C2: 0 | D2: 17.12675 | E2: 17.093088 | F2: 17.155108 | G2: 17.123877 | H2: 17.136379 | I2: 17.092359 | J2: 17.169574 | K2: 17.15059 | L2: 16.946524 | M2: 20.158553 | N2: 20.09952 | O2: 31.486344 | P2: 31.771969 | Q2: 29.643045 | R2: 29.839126 | S2: 13.52512 | T2: -6972.306 | U2: 30.424603 | V2: 30.599239 | W2: 28.930039 | X2: -2008.0698 | Y2: 21.523513 | Z2: 17.090816 | AA2: 17.125916 | AB2: 17.077947 | AC2: 17.16031 | AD2: 20.131751 | AE2: 29.769103 | AF2: 21.517516 | AG2: 30.482075 | AH2: 31.641662 | AI2: 0.4 | AJ2: 1.2043543 | AK2: -2033.4862 | AL2: -2038.3009 | AM2: 790.14858 | AN2: -451.40372 | AO2: 3.7158899 | AP2: 3.7307509 | AQ2: 5.1838277 | AR2: -2826.0998 | AS2: -7.1249504 | AT2: -2024.4018 | AU2: 503 | AV2: 15.044111 | AW2: 5 | AX2: -23.524459
A3: 75 | B3: 1 | C3: 0 | D3: 17.355872 | E3: 17.327882 | F3: 17.412764 | G3: 17.381552 | H3: 17.369786 | I3: 17.338466 | J3: 17.388611 | K3: 17.415788 | L3: 17.060327 | M3: 20.740143 | N3: 20.686294 | O3: 31.836868 | P3: 32.294083 | Q3: 29.914495 | R3: 30.078729 | S3: 15.15928 | T3: -6927.625 | U3: 30.739787 | V3: 30.898329 | W3: 29.225166 | X3: -2008.6445 | Y3: 21.653118 | Z3: 17.342915 | AA3: 17.375976 | AB3: 17.346551 | AC3: 17.384261 | AD3: 20.709221 | AE3: 30.054897 | AF3: 21.658739 | AG3: 30.852515 | AH3: 32.083026 | AI3: 0.4 | AJ3: 1.0895311 | AK3: 10.42672 | AL3: 7.9140407 | AM3: 1040.5353 | AN3: -498.81709 | AO3: 5.1297982 | AP3: 5.1297982 | AQ3: 5.1867506 | AR3: -2826.0332 | AS3: -7.28413 | AT3: -2024.3814 | AU3: 503 | AV3: 21 | AW3: 5 | AX3: 160
A4: 75 | B4: 1 | C4: 0 | D4: 17.355872 | E4: 17.327882 | F4: 17.412764 | G4: 17.386382 | H4: 17.373204 | I4: 17.344144 | J4: 17.388611 | K4: 17.415788 | L4: 17.060327 | M4: 20.751985 | N4: 20.695188 | O4: 31.835943 | P4: 32.295635 | Q4: 29.913131 | R4: 30.073669 | S4: 15.155032 | T4: -6927.6284 | U4: 30.741131 | V4: 30.897724 | W4: 29.225103 | X4: -2008.6429 | Y4: 21.660753 | Z4: 17.342915 | AA4: 17.375976 | AB4: 17.351445 | AC4: 17.384261 | AD4: 20.720298 | AE4: 30.053079 | AF4: 21.664249 | AG4: 30.850374 | AH4: 32.085114 | AI4: 0.4 | AJ4: 1.0895311 | AK4: 10.426727 | AL4: 7.9133312 | AM4: 1040.5188 | AN4: -498.83434 | AO4: 5.1297982 | AP4: 5.1297982 | AQ4: 5.1867506 | AR4: -2826.035 | AS4: -7.28413 | AT4: -2024.383 | AU4: 503 | AV4: 21 | AW4: 5 | AX4: 160
A5: 75 | B5: 1 | C5: 0 | D5: 17.355872 | E5: 17.327882 | F5: 17.412764 | G5: 17.386382 | H5: 17.373204 | I5: 17.350747 | J5: 17.393869 | K5: 17.415788 | L5: 17.060327 | M5: 20.742258 | N5: 20.690947 | O5: 31.840419 | P5: 32.30304 | Q5: 29.922721 | R5: 30.079797 | S5: 15.164607 | T5: -6927.6317 | U5: 30.752104 | V5: 30.910279 | W5: 29.220298 | X5: -2008.6413 | Y5: 21.660753 | Z5: 17.342915 | AA5: 17.375976 | AB5: 17.351445 | AC5: 17.389509 | AD5: 20.720546 | AE5: 30.065555 | AF5: 21.669338 | AG5: 30.853781 | AH5: 32.095397 | AI5: 0.4 | AJ5: 1.0895311 | AK5: 10.441391 | AL5: 7.914685 | AM5: 1040.7482 | AN5: -499.00956 | AO5: 5.1297982 | AP5: 5.1297982 | AQ5: 5.1867506 | AR5: -2826.035 | AS5: -7.28413 | AT5: -2024.383 | AU5: 503 | AV5: 21 | AW5: 10 | AX5: 160
A6: 135 | B6: 1 | C6: 0 | D6: 17.594867 | E6: 17.577308 | F6: 17.635667 | G6: 17.630368 | H6: 17.630412 | I6: 17.578631 | J6: 17.653892 | K6: 17.65234 | L6: 17.192085 | M6: 20.721016 | N6: 20.69571 | O6: 32.266598 | P6: 32.60084 | Q6: 30.257142 | R6: 30.431919 | S6: 15.071614 | T6: -7009.1256 | U6: 31.024055 | V6: 31.198595 | W6: 29.495973 | X6: -2008.6033 | Y6: 21.707785 | Z6: 17.585917 | AA6: 17.61916 | AB6: 17.598739 | AC6: 17.644475 | AD6: 20.697716 | AE6: 30.404514 | AF6: 21.692008 | AG6: 31.124879 | AH6: 32.496051 | AI6: 0.5 | AJ6: 1.0854578 | AK6: 10.957275 | AL6: 8.3240237 | AM6: 1031.2666 | AN6: -499.76984 | AO6: 4.7849835 | AP6: 4.7849835 | AQ6: 5.1874962 | AR6: -2826.0332 | AS6: -7.253202 | AT6: -2024.3127 | AU6: 503 | AV6: 21 | AW6: 10 | AX6: 320
A7: 135 | B7: 1 | C7: 0 | D7: 17.598951 | E7: 17.577308 | F7: 17.635667 | G7: 17.630368 | H7: 17.634816 | I7: 17.578631 | J7: 17.653892 | K7: 17.656354 | L7: 17.192085 | M7: 20.721016 | N7: 20.70063 | O7: 32.295794 | P7: 32.62792 | Q7: 30.275537 | R7: 30.447888 | S7: 15.073553 | T7: -7009.1256 | U7: 31.037386 | V7: 31.225823 | W7: 29.52179 | X7: -2008.6018 | Y7: 21.698728 | Z7: 17.589886 | AA7: 17.615476 | AB7: 17.598739 | AC7: 17.644475 | AD7: 20.702156 | AE7: 30.419637 | AF7: 21.693982 | AG7: 31.157855 | AH7: 32.49362 | AI7: 0.5 | AJ7: 1.0904475 | AK7: 10.953793 | AL7: 8.3245618 | AM7: 1031.139 | AN7: -499.64255 | AO7: 4.7849835 | AP7: 4.7849835 | AQ7: 5.1874962 | AR7: -2826.0332 | AS7: -7.244032 | AT7: -2024.3127 | AU7: 503 | AV7: 22 | AW7: 10 | AX7: 320
A8: 135 | B8: 1 | C8: 0 | D8: 17.598951 | E8: 17.577308 | F8: 17.635667 | G8: 17.626695 | H8: 17.634816 | I8: 17.578631 | J8: 17.653892 | K8: 17.658448 | L8: 17.192085 | M8: 20.726746 | N8: 20.702542 | O8: 32.304537 | P8: 32.640502 | Q8: 30.279292 | R8: 30.429175 | S8: 15.068677 | T8: -7009.1256 | U8: 31.039774 | V8: 31.233768 | W8: 29.521356 | X8: -2008.6018 | Y8: 21.697336 | Z8: 17.591625 | AA8: 17.613727 | AB8: 17.598739 | AC8: 17.644475 | AD8: 20.709298 | AE8: 30.417301 | AF8: 21.686242 | AG8: 31.159358 | AH8: 32.512161 | AI8: 0.5 | AJ8: 1.0904475 | AK8: 10.956479 | AL8: 8.3301562 | AM8: 1031.0758 | AN8: -499.75646 | AO8: 4.7849835 | AP8: 4.7849835 | AQ8: 5.1874962 | AR8: -2826.0332 | AS8: -7.2420424 | AT8: -2024.3127 | AU8: 503 | AV8: 22 | AW8: 19.940839 | AX8: 320
A9: 195 | B9: 1 | C9: 0 | D9: 18.070933 | E9: 18.054576 | F9: 18.149953 | G9: 18.097124 | H9: 18.091739 | I9: 18.057203 | J9: 18.121369 | K9: 18.162865 | L9: 17.437041 | M9: 22.036742 | N9: 22.011264 | O9: 42.685776 | P9: 43.381137 | Q9: 40.208599 | R9: 40.254988 | S9: 12.961345 | T9: -6927.6284 | U9: 39.914781 | V9: 39.956196 | W9: 37.519755 | X9: -2005.0706 | Y9: 23.924866 | Z9: 18.04946 | AA9: 18.105233 | AB9: 18.060043 | AC9: 18.128223 | AD9: 22.036781 | AE9: 40.287495 | AF9: 23.95834 | AG9: 39.926365 | AH9: 43.072143 | AI9: 0.6 | AJ9: 1.9872392 | AK9: 18.991682 | AL9: 14.548286 | AM9: 1425.313 | AN9: 3.9803575 | AO9: 6.7524868 | AP9: 6.6449831 | AQ9: 5.1874962 | AR9: -2826.0315 | AS9: -6.9259142 | AT9: -2024.3174 | AU9: 503 | AV9: 22 | AW9: 25 | AX9: 480
A10: 195 | B10: 1 | C10: 0 | D10: 18.07364 | E10: 18.058182 | F10: 18.15254 | G10: 18.099682 | H10: 18.092551 | I10: 18.057203 | J10: 18.125649 | K10: 18.165449 | L10: 17.437041 | M10: 22.055013 | N10: 22.015617 | O10: 42.693251 | P10: 43.385981 | Q10: 40.222238 | R10: 40.266777 | S10: 12.984997 | T10: -6972.3165 | U10: 39.927257 | V10: 39.968044 | W10: 37.529715 | X10: -2005.0657 | Y10: 23.938013 | Z10: 18.050593 | AA10: 18.105233 | AB10: 18.060043 | AC10: 18.129504 | AD10: 22.060381 | AE10: 40.298736 | AF10: 23.969626 | AG10: 39.929665 | AH10: 43.067572 | AI10: 0.6 | AJ10: 1.9872392 | AK10: 18.991702 | AL10: 14.549792 | AM10: 1425.9931 | AN10: 4.0782276 | AO10: 6.7524868 | AP10: 6.6449831 | AQ10: 5.1874962 | AR10: -2826.0315 | AS10: -6.9259142 | AT10: -2024.3174 | AU10: 503 | AV10: 22.662723 | AW10: 25 | AX10: 480
A11: 195 | B11: 1 | C11: 0 | D11: 18.07364 | E11: 18.058182 | F11: 18.15254 | G11: 18.099682 | H11: 18.092551 | I11: 18.057203 | J11: 18.124045 | K11: 18.16342 | L11: 17.437041 | M11: 22.059052 | N11: 22.010916 | O11: 42.70032 | P11: 43.383879 | Q11: 40.228394 | R11: 40.270098 | S11: 12.985787 | T11: -6972.3199 | U11: 39.932879 | V11: 39.973836 | W11: 37.533875 | X11: -2005.0657 | Y11: 23.938123 | Z11: 18.050593 | AA11: 18.099249 | AB11: 18.060043 | AC11: 18.129504 | AD11: 22.060615 | AE11: 40.304721 | AF11: 23.973345 | AG11: 39.935134 | AH11: 43.069101 | AI11: 0.6 | AJ11: 1.9890392 | AK11: 18.994697 | AL11: 14.54824 | AM11: 1426.1055 | AN11: 4.1092079 | AO11: 6.7524868 | AP11: 6.6449831 | AQ11: 5.1874962 | AR11: -2826.0315 | AS11: -6.9215793 | AT11: -2024.3174 | AU11: 503 | AV11: 23 | AW11: 28.260441 | AX11: 480
A12: 255 | B12: 1 | C12: 0 | D12: 18.874282 | E12: 18.852248 | F12: 18.941056 | G12: 18.914302 | H12: 18.89371 | I12: 18.849044 | J12: 18.924577 | K12: 18.954129 | L12: 17.862168 | M12: 23.148272 | N12: 23.050376 | O12: 47.970798 | P12: 48.897994 | Q12: 45.047897 | R12: 45.058802 | S12: 11.729745 | T12: -6972.3186 | U12: 44.406521 | V12: 44.394984 | W12: 41.639972 | X12: -2002.2238 | Y12: 25.415032 | Z12: 18.84686 | AA12: 18.916766 | AB12: 18.853403 | AC12: 18.917732 | AD12: 23.082575 | AE12: 45.105428 | AF12: 25.459165 | AG12: 44.397055 | AH12: 48.460043 | AI12: 0.4 | AJ12: 2.3786994 | AK12: 22.684173 | AL12: 17.581025 | AM12: 1664.5299 | AN12: 262.95436 | AO12: 7.7096389 | AP12: 7.6279108 | AQ12: 5.1874962 | AR12: -2826.0332 | AS12: -6.7958858 | AT12: -2024.2826 | AU12: 503 | AV12: 23 | AW12: 33 | AX12: 560
A13: 255 | B13: 1 | C13: 0 | D13: 18.875705 | E13: 18.852248 | F13: 18.942961 | G13: 18.914302 | H13: 18.895227 | I13: 18.854526 | J13: 18.924577 | K13: 18.959584 | L13: 17.866291 | M13: 23.14155 | N13: 23.055387 | O13: 47.953642 | P13: 48.889957 | Q13: 45.032725 | R13: 45.043771 | S13: 11.754135 | T13: -6972.3186 | U13: 44.397898 | V13: 44.388637 | W13: 41.630468 | X13: -2002.2286 | Y13: 25.404667 | Z13: 18.85137 | AA13: 18.916766 | AB13: 18.858551 | AC13: 18.922515 | AD13: 23.080294 | AE13: 45.090305 | AF13: 25.442874 | AG13: 44.392103 | AH13: 48.45085 | AI13: 0.4 | AJ13: 2.3850142 | AK13: 22.679596 | AL13: 17.582003 | AM13: 1664.5327 | AN13: 262.75118 | AO13: 7.7096389 | AP13: 7.6279108 | AQ13: 5.1874962 | AR13: -2826.0332 | AS13: -6.7958858 | AT13: -2024.2826 | AU13: 503 | AV13: 23 | AW13: 33 | AX13: 560
... A29: 525 | B29: 1 | C29: 0 | D29: 21.140392 | E29: 21.105952 | F29: 21.191777 | G29: 21.142888 | H29: 21.133684 | I29: 21.086761 | J29: 21.177315 | K29: 21.178856 | L29: 19.887629 | M29: 20.929624 | N29: 20.905843 | O29: 32.434998 | P29: 32.828275 | Q29: 30.529711 | R29: 30.639384 | S29: 15.318352 | T29: -6813.2625 | U29: 31.244991 | V29: 31.428072 | W29: 29.70982 | X29: -2007.8635 | Y29: 21.86702 | Z29: 21.115482 | AA29: 21.155388 | AB29: 21.119069 | AC29: 21.166062 | AD29: 20.93653 | AE29: 30.637461 | AF29: 21.868487 | AG29: 31.350441 | AH29: 32.667188 | AI29: 0.1 | AJ29: 1.1102508 | AK29: 10.902125 | AL29: 8.2516061 | AM29: 1047.3717 | AN29: -480.13209 | AO29: 4.7849835 | AP29: 4.7536368 | AQ29: 5.1874962 | AR29: -2826.0315 | AS29: -7.0739022 | AT29: -2024.4237 | AU29: 503 | AV29: 27 | AW29: -4.2900684 | AX29: 160

Sheet mean+3Sigma
A1: Time | B1: Status (0-off 1-on) | C1: Group (0-standalone 1-Group lead 2-Group follow) | D1: TT01 | E1: TT02 | F1: TT31 | G1: TT41 | H1: TT61 | I1: TT62 | J1: TT51 | K1: TT52 | L1: TT45 | M1: PT01 | N1: PT02 | O1: PT31 | P1: PT41 | Q1: PT32 | R1: PT42 | S1: PT21 | T1: PT11 | U1: PT51 | V1: PT52 | W1: PT53 | X1: PT61 | Y1: PT62 | Z1: TT01/TT02 | AA1: TT31/TT41 | AB1: TT61/TT62 | AC1: TT51/TT52 | AD1: PT01/PT02 | AE1: PT32/PT42 | AF1: PT61/PT62 | AG1: PT51/PT52 | AH1: Pump 31 Filter DP | AI1: Pump 41 Filter DP | AJ1: Primary Filter 53 DP | AK1: Secondary DP (Supply - Return) | AL1: Primary DP (Supply - Return) | AM1: FT01 | AN1: FT61 | AO1: P31 Speed % | AP1: P41 Speed % | AQ1: FCV61 Actual Flow% | AR1: FCV61 Actual Open% | AS1: Air Humidity | AT1: Air Temperature | AU1: Program version | AV1: Secondary Temperature Setpoint | AW1: Secondary DP Setpoint | AX1: Secondary Flow Setpoint
A2: 15 | B2: 1 | C2: 0 | D2: 37.392298 | E2: 37.437865 | F2: 37.392511 | G2: 37.378504 | H2: 37.356478 | I2: 37.414784 | J2: 37.342331 | K2: 37.382743 | L2: 35.803476 | M2: 30.303352 | N2: 30.231433 | O2: 50.285085 | P2: 50.456602 | Q2: 47.014098 | R2: 46.934684 | S2: 23.796308 | T2: 10561.189 | U2: 46.987302 | V2: 46.815047 | W2: 44.496151 | X2: 2215.8032 | Y2: 31.916964 | Z2: 37.411565 | AA2: 37.369322 | AB2: 37.391101 | AC2: 37.325404 | AD2: 30.261106 | AE2: 46.930897 | AF2: 31.811055 | AG2: 46.917925 | AH2: 50.341671 | AI2: 4.0285265 | AJ2: 2.7694552 | AK2: 2220.86 | AL2: 2218.4294 | AM2: 2357.7133 | AN2: 3176.6347 | AO2: 8.6103005 | AP2: 8.5978206 | AQ2: 14.328077 | AR2: 3157.3903 | AS2: 42.636855 | AT2: 2225.2399 | AU2: 503 | AV2: 27.40827 | AW2: 5 | AX2: 243.76255
A3: 75 | B3: 1 | C3: 0 | D3: 37.570318 | E3: 37.612594 | F3: 37.563426 | G3: 37.573209 | H3: 37.51831 | I3: 37.571058 | J3: 37.568532 | K3: 37.558021 | L3: 36.134912 | M3: 29.438428 | N3: 29.368468 | O3: 43.417894 | P3: 43.33925 | Q3: 40.783124 | R3: 40.749842 | S3: 23.731196 | T3: 10360.485 | U3: 41.434023 | V3: 41.294528 | W3: 39.474834 | X3: 2215.5111 | Y3: 30.923072 | Z3: 37.566608 | AA3: 37.559738 | AB3: 37.527259 | AC3: 37.551454 | AD3: 29.400303 | AE3: 40.68796 | AF3: 30.798404 | AG3: 41.316533 | AH3: 43.359831 | AI3: 3.4626528 | AJ3: 2.3890404 | AK3: 15.237566 | AL3: 11.81215 | AM3: 1885.5766 | AN3: 3006.6504 | AO3: 6.1059161 | AP3: 6.1059161 | AQ3: 14.332297 | AR3: 3157.4142 | AS3: 42.629368 | AT3: 2225.2504 | AU3: 503 | AV3: 21 | AW3: 5 | AX3: 160
A4: 75 | B4: 1 | C4: 0 | D4: 37.570318 | E4: 37.612594 | F4: 37.563426 | G4: 37.570761 | H4: 37.517272 | I4: 37.570142 | J4: 37.568532 | K4: 37.558021 | L4: 36.134912 | M4: 29.426587 | N4: 29.359574 | O4: 43.418819 | P4: 43.337698 | Q4: 40.78925 | R4: 40.762045 | S4: 23.735444 | T4: 10360.486 | U4: 41.444583 | V4: 41.304657 | W4: 39.477278 | X4: 2215.5119 | Y4: 30.915437 | Z4: 37.566608 | AA4: 37.559738 | AB4: 37.524745 | AC4: 37.551454 | AD4: 29.391606 | AE4: 40.704064 | AF4: 30.785751 | AG4: 41.325817 | AH4: 43.360124 | AI4: 3.4637169 | AJ4: 2.3890404 | AK4: 15.242321 | AL4: 11.810478 | AM4: 1885.486 | AN4: 3006.601 | AO4: 6.1059161 | AP4: 6.1059161 | AQ4: 14.332297 | AR4: 3157.4136 | AS4: 42.629368 | AT4: 2225.2497 | AU4: 503 | AV4: 21 | AW4: 5 | AX4: 160
A5: 75 | B5: 1 | C5: 0 | D5: 37.570318 | E5: 37.612594 | F5: 37.563426 | G5: 37.570761 | H5: 37.517272 | I5: 37.56592 | J5: 37.565655 | K5: 37.558021 | L5: 36.134912 | M5: 29.431552 | N5: 29.359053 | O5: 43.426248 | P5: 43.342198 | Q5: 40.796327 | R5: 40.765442 | S5: 23.723488 | T5: 10360.486 | U5: 41.438372 | V5: 41.299245 | W5: 39.482083 | X5: 2215.5127 | Y5: 30.915437 | Z5: 37.566608 | AA5: 37.559738 | AB5: 37.524745 | AC5: 37.548586 | AD5: 29.391359 | AE5: 40.710636 | AF5: 30.785424 | AG5: 41.329552 | AH5: 43.361746 | AI5: 3.4653167 | AJ5: 2.3890404 | AK5: 15.244324 | AL5: 11.804363 | AM5: 1885.4899 | AN5: 3006.5357 | AO5: 6.1059161 | AP5: 6.1059161 | AQ5: 14.332297 | AR5: 3157.4136 | AS5: 42.629368 | AT5: 2225.2497 | AU5: 503 | AV5: 21 | AW5: 10 | AX5: 160
A6: 135 | B6: 1 | C6: 0 | D6: 37.745609 | E6: 37.777454 | F6: 37.745285 | G6: 37.73868 | H6: 37.681493 | I6: 37.757083 | J6: 37.717536 | K6: 37.738136 | L6: 36.362677 | M6: 29.49327 | N6: 29.411433 | O6: 43.102449 | P6: 43.161065 | Q6: 40.561906 | R6: 40.534748 | S6: 23.845052 | T6: 10754.057 | U6: 41.26404 | V6: 41.103786 | W6: 39.315932 | X6: 2215.5319 | Y6: 30.925548 | Z6: 37.740274 | AA6: 37.728459 | AB6: 37.703642 | AC6: 37.698382 | AD6: 29.457046 | AE6: 40.4812 | AF6: 30.817516 | AG6: 41.167978 | AH6: 43.070616 | AI6: 3.4128562 | AJ6: 2.3788279 | AK6: 14.802249 | AL6: 11.447405 | AM6: 1888.9596 | AN6: 3005.2484 | AO6: 6.4769212 | AP6: 6.4769212 | AQ6: 14.333932 | AR6: 3157.4142 | AS6: 42.462726 | AT6: 2225.1865 | AU6: 503 | AV6: 21 | AW6: 10 | AX6: 320
A7: 135 | B7: 1 | C7: 0 | D7: 37.743906 | E7: 37.777454 | F7: 37.745285 | G7: 37.73868 | H7: 37.67947 | I7: 37.757083 | J7: 37.717536 | K7: 37.736503 | L7: 36.362677 | M7: 29.49327 | N7: 29.406513 | O7: 43.08754 | P7: 43.14827 | Q7: 40.553034 | R7: 40.514017 | S7: 23.847875 | T7: 10754.057 | U7: 41.25309 | V7: 41.083701 | W7: 39.294876 | X7: 2215.5327 | Y7: 30.934605 | Z7: 37.738685 | AA7: 37.734524 | AB7: 37.703642 | AC7: 37.698382 | AD7: 29.454987 | AE7: 40.461315 | AF7: 30.822685 | AG7: 41.139764 | AH7: 43.073047 | AI7: 3.4183558 | AJ7: 2.3738382 | AK7: 14.798588 | AL7: 11.439724 | AM7: 1889.1205 | AN7: 3005.2902 | AO7: 6.4769212 | AP7: 6.4769212 | AQ7: 14.333932 | AR7: 3157.4142 | AS7: 42.448794 | AT7: 2225.1865 | AU7: 503 | AV7: 22 | AW7: 10 | AX7: 320
A8: 135 | B8: 1 | C8: 0 | D8: 37.743906 | E8: 37.777454 | F8: 37.745285 | G8: 37.744734 | H8: 37.67947 | I8: 37.757083 | J8: 37.717536 | K8: 37.73679 | L8: 36.362677 | M8: 29.48992 | N8: 29.409363 | O8: 43.078796 | P8: 43.142832 | Q8: 40.54928 | R8: 40.535111 | S8: 23.859895 | T8: 10754.057 | U8: 41.248321 | V8: 41.078136 | W8: 39.297692 | X8: 2215.5327 | Y8: 30.935997 | Z8: 37.739328 | AA8: 37.733892 | AB8: 37.703642 | AC8: 37.698382 | AD8: 29.450226 | AE8: 40.473175 | AF8: 30.830425 | AG8: 41.138261 | AH8: 43.068791 | AI8: 3.4165885 | AJ8: 2.3738382 | AK8: 14.800664 | AL8: 11.438891 | AM8: 1889.1813 | AN8: 3005.2303 | AO8: 6.4769212 | AP8: 6.4769212 | AQ8: 14.333932 | AR8: 3157.4142 | AS8: 42.449185 | AT8: 2225.1865 | AU8: 503 | AV8: 22 | AW8: 29.702018 | AX8: 320
A9: 195 | B9: 1 | C9: 0 | D9: 38.131448 | E9: 38.181138 | F9: 38.15719 | G9: 38.162399 | H9: 38.101118 | I9: 38.14994 | J9: 38.152441 | K9: 38.132373 | L9: 36.636769 | M9: 31.320401 | N9: 31.169688 | O9: 60.885653 | P9: 61.080768 | Q9: 56.574734 | R9: 56.645012 | S9: 21.212464 | T9: 10360.486 | U9: 55.5376 | V9: 55.508089 | W9: 52.375483 | X9: 2217.3158 | Y9: 33.963229 | Z9: 38.141016 | AA9: 38.159052 | AB9: 38.104243 | AC9: 38.140825 | AD9: 31.217981 | AE9: 56.555362 | AF9: 33.872613 | AG9: 55.516492 | AH9: 60.958809 | AI9: 5.1053247 | AJ9: 3.5675227 | AK9: 29.620222 | AL9: 23.082667 | AM9: 2571.5299 | AN9: 3330.4554 | AO9: 8.6808466 | AP9: 8.7907312 | AQ9: 14.333932 | AR9: 3157.4148 | AS9: 42.01639 | AT9: 2225.1841 | AU9: 503 | AV9: 22 | AW9: 25 | AX9: 480
A10: 195 | B10: 1 | C10: 0 | D10: 38.133503 | E10: 38.179913 | F10: 38.156984 | G10: 38.162222 | H10: 38.102687 | I10: 38.14994 | J10: 38.150542 | K10: 38.13217 | L10: 36.636769 | M10: 31.30213 | N10: 31.158192 | O10: 60.890082 | P10: 61.075924 | Q10: 56.570619 | R10: 56.635604 | S10: 21.198336 | T10: 10561.209 | U10: 55.529886 | V10: 55.501003 | W10: 52.365523 | X10: 2217.3181 | Y10: 33.947702 | Z10: 38.142264 | AA10: 38.159052 | AB10: 38.104243 | AC10: 38.141924 | AD10: 31.196762 | AE10: 56.551264 | AF10: 33.863708 | AG10: 55.513192 | AH10: 60.958618 | AI10: 5.1023003 | AJ10: 3.5675227 | AK10: 29.615441 | AL10: 23.08116 | AM10: 2571.1236 | AN10: 3330.4956 | AO10: 8.6808466 | AP10: 8.7907312 | AQ10: 14.333932 | AR10: 3157.4148 | AS10: 42.01639 | AT10: 2225.1841 | AU10: 503 | AV10: 23.313468 | AW10: 25 | AX10: 480
A11: 195 | B11: 1 | C11: 0 | D11: 38.133503 | E11: 38.179913 | F11: 38.156984 | G11: 38.162222 | H11: 38.102687 | I11: 38.14994 | J11: 38.154526 | K11: 38.13658 | L11: 36.636769 | M11: 31.300471 | N11: 31.167655 | O11: 60.883014 | P11: 61.080407 | Q11: 56.559701 | R11: 56.639426 | S11: 21.195165 | T11: 10561.21 | U11: 55.529026 | V11: 55.499974 | W11: 52.358983 | X11: 2217.3181 | Y11: 33.94521 | Z11: 38.142264 | AA11: 38.167418 | AB11: 38.104243 | AC11: 38.141924 | AD11: 31.196528 | AE11: 56.552421 | AF11: 33.862369 | AG11: 55.512485 | AH11: 60.964232 | AI11: 5.0985555 | AJ11: 3.5704846 | AK11: 29.62197 | AL11: 23.087474 | AM11: 2571.1826 | AN11: 3330.5646 | AO11: 8.6808466 | AP11: 8.7907312 | AQ11: 14.333932 | AR11: 3157.4148 | AS11: 42.012055 | AT11: 2225.1841 | AU11: 503 | AV11: 23 | AW11: 37.168131 | AX11: 480
A12: 255 | B12: 1 | C12: 0 | D12: 38.830479 | E12: 38.881085 | F12: 38.887515 | G12: 38.876174 | H12: 38.801528 | I12: 38.865242 | J12: 38.884946 | K12: 38.86968 | L12: 37.102118 | M12: 33.087442 | N12: 32.96391 | O12: 74.564916 | P12: 75.149625 | Q12: 69.516389 | R12: 69.593579 | S12: 20.151207 | T12: 10561.204 | U12: 66.953003 | V12: 66.957397 | W12: 62.769552 | X12: 2218.7548 | Y12: 36.668301 | Z12: 38.836473 | AA12: 38.864187 | AB12: 38.822788 | AC12: 38.867982 | AD12: 33.031711 | AE12: 69.499334 | AF12: 36.647978 | AG12: 66.957707 | AH12: 74.82091 | AI12: 6.1908373 | AJ12: 4.5713006 | AK12: 40.827732 | AL12: 31.668975 | AM12: 2772.6177 | AN12: 3528.4956 | AO12: 9.9760754 | AP12: 9.9625654 | AQ12: 14.333932 | AR12: 3157.4142 | AS12: 41.743505 | AT12: 2225.1516 | AU12: 503 | AV12: 23 | AW12: 33 | AX12: 560
A13: 255 | B13: 1 | C13: 0 | D13: 38.833819 | E13: 38.881085 | F13: 38.887991 | G13: 38.876174 | H13: 38.804773 | I13: 38.862141 | J13: 38.884946 | K13: 38.866606 | L13: 37.100375 | M13: 33.091783 | N13: 32.96366 | O13: 74.558263 | P13: 75.145758 | Q13: 69.517275 | R13: 69.577657 | S13: 20.141103 | T13: 10561.204 | U13: 66.94734 | V13: 66.951839 | W13: 62.762389 | X13: 2218.7524 | Y13: 36.671523 | Z13: 38.836725 | AA13: 38.864187 | AB13: 38.822401 | AC13: 38.86558 | AD13: 33.031611 | AE13: 69.490648 | AF13: 36.652364 | AG13: 66.953135 | AH13: 74.815816 | AI13: 6.1939203 | AJ13: 4.5721286 | AK13: 40.81088 | AL13: 31.665616 | AM13: 2772.6483 | AN13: 3528.4607 | AO13: 9.9760754 | AP13: 9.9625654 | AQ13: 14.333932 | AR13: 3157.4142 | AS13: 41.743505 | AT13: 2225.1516 | AU13: 503 | AV13: 23 | AW13: 33 | AX13: 560
... A29: 525 | B29: 1 | C29: 0 | D29: 40.861989 | E29: 40.915477 | F29: 40.867747 | G29: 40.869017 | H29: 40.840125 | I29: 40.901334 | J29: 40.865543 | K29: 40.88781 | L29: 38.981419 | M29: 30.4299 | N29: 30.346538 | O29: 43.960241 | P29: 44.00982 | Q29: 41.358384 | R29: 41.341568 | S29: 24.741172 | T29: 9934.0529 | U29: 42.097866 | V29: 41.931451 | W29: 40.133037 | X29: 2215.9064 | Y29: 31.902028 | Z29: 40.867851 | AA29: 40.856516 | AB29: 40.842835 | AC29: 40.855367 | AD29: 30.377755 | AE29: 41.28873 | AF29: 31.783894 | AG29: 41.990035 | AH29: 43.939954 | AI29: 3.532892 | AJ29: 2.404035 | AK29: 14.740732 | AL29: 11.446013 | AM29: 1935.483 | AN29: 3020.6892 | AO29: 6.4769212 | AP29: 6.510649 | AQ29: 14.333932 | AR29: 3157.4148 | AS29: 42.14295 | AT29: 2225.2785 | AU29: 503 | AV29: 27 | AW29: 10.361497 | AX29: 160

Sheet min
A1: Time | B1: Status (0-off 1-on) | C1: Group (0-standalone 1-Group lead 2-Group follow) | D1: TT01 | E1: TT02 | F1: TT31 | G1: TT41 | H1: TT61 | I1: TT62 | J1: TT51 | K1: TT52 | L1: TT45 | M1: PT01 | N1: PT02 | O1: PT31 | P1: PT41 | Q1: PT32 | R1: PT42 | S1: PT21 | T1: PT11 | U1: PT51 | V1: PT52 | W1: PT53 | X1: PT61 | Y1: PT62 | Z1: TT01/TT02 | AA1: TT31/TT41 | AB1: TT61/TT62 | AC1: TT51/TT52 | AD1: PT01/PT02 | AE1: PT32/PT42 | AF1: PT61/PT62 | AG1: PT51/PT52 | AH1: Pump 31 Filter DP | AI1: Pump 41 Filter DP | AJ1: Primary Filter 53 DP | AK1: Secondary DP (Supply - Return) | AL1: Primary DP (Supply - Return) | AM1: FT01 | AN1: FT61 | AO1: P31 Speed % | AP1: P41 Speed % | AQ1: FCV61 Actual Flow% | AR1: FCV61 Actual Open% | AS1: Air Humidity | AT1: Air Temperature | AU1: Program version | AV1: Secondary Temperature Setpoint | AW1: Secondary DP Setpoint | AX1: Secondary Flow Setpoint
A2: 15 | B2: 1 | C2: 0 | D2: 21.3 | E2: 21.4 | F2: 21.5 | G2: 21.4 | H2: 21.4 | I2: 21.3 | J2: 21.4 | K2: 21.4 | L2: 20.9 | M2: 18.3 | N2: 18.3 | O2: 23.9 | P2: 23.9 | Q2: 22.8 | R2: 23.4 | S2: 13.8 | T2: 0 | U2: 25.3 | V2: 25.6 | W2: 24.7 | X2: 20.6 | Y2: 20.6 | Z2: 21.3 | AA2: 21.4 | AB2: 21.3 | AC2: 21.4 | AD2: 18.3 | AE2: 23.1 | AF2: 20.6 | AG2: 25.4 | AH2: 23.9 | AI2: 0.4 | AJ2: 0.8 | AK2: 11.9 | AL2: 6.6 | AM2: 4.3 | AN2: 0 | AO2: 0 | AP2: 0 | AQ2: 0 | AR2: 7.4 | AS2: 5.7 | AT2: 1.5 | AU2: 15 | AV2: 21 | AW2: 5 | AX2: 100
A3: 75 | B3: 1 | C3: 0 | D3: 21.6 | E3: 21.6 | F3: 21.7 | G3: 21.7 | H3: 21.6 | I3: 21.6 | J3: 21.6 | K3: 21.7 | L3: 21.1 | M3: 22.2 | N3: 22.1 | O3: 27.6 | P3: 28.4 | Q3: 26.2 | R3: 26.2 | S3: 17 | T3: 0 | U3: 27.3 | V3: 27.7 | W3: 26.7 | X3: 22.7 | Y3: 22.7 | Z3: 21.6 | AA3: 21.7 | AB3: 21.6 | AC3: 21.6 | AD3: 22.2 | AE3: 26.2 | AF3: 22.7 | AG3: 27.5 | AH3: 28 | AI3: 0.4 | AJ3: 0.8 | AK3: 6.6 | AL3: 4.8 | AM3: 1099.7 | AN3: 694.3 | AO3: 5.6 | AP3: 5.6 | AQ3: 0 | AR3: 9.9 | AS3: 5.7 | AT3: 1.4 | AU3: 15 | AV3: 21 | AW3: 5 | AX3: 160
A4: 75 | B4: 1 | C4: 0 | D4: 21.6 | E4: 21.6 | F4: 21.7 | G4: 21.7 | H4: 21.6 | I4: 21.6 | J4: 21.6 | K4: 21.7 | L4: 21.1 | M4: 22.2 | N4: 22.1 | O4: 27.6 | P4: 28.4 | Q4: 26.2 | R4: 26.2 | S4: 17 | T4: 0 | U4: 27.3 | V4: 27.7 | W4: 26.7 | X4: 22.7 | Y4: 22.7 | Z4: 21.6 | AA4: 21.7 | AB4: 21.6 | AC4: 21.6 | AD4: 22.2 | AE4: 26.2 | AF4: 22.7 | AG4: 27.5 | AH4: 28 | AI4: 0.4 | AJ4: 0.8 | AK4: 6.6 | AL4: 4.8 | AM4: 1099.7 | AN4: 694.3 | AO4: 5.6 | AP4: 5.6 | AQ4: 0 | AR4: 9.9 | AS4: 5.7 | AT4: 1.4 | AU4: 15 | AV4: 21 | AW4: 5 | AX4: 160
A5: 75 | B5: 1 | C5: 0 | D5: 21.6 | E5: 21.6 | F5: 21.7 | G5: 21.7 | H5: 21.6 | I5: 21.6 | J5: 21.6 | K5: 21.7 | L5: 21.1 | M5: 22.2 | N5: 22.1 | O5: 27.6 | P5: 28.4 | Q5: 26.2 | R5: 26.2 | S5: 17 | T5: 0 | U5: 27.3 | V5: 27.7 | W5: 26.7 | X5: 22.7 | Y5: 22.7 | Z5: 21.6 | AA5: 21.7 | AB5: 21.6 | AC5: 21.6 | AD5: 22.2 | AE5: 26.2 | AF5: 22.7 | AG5: 27.5 | AH5: 28 | AI5: 0.4 | AJ5: 0.8 | AK5: 6.6 | AL5: 4.8 | AM5: 1096.8 | AN5: 694.3 | AO5: 5.6 | AP5: 5.6 | AQ5: 0 | AR5: 9.9 | AS5: 5.7 | AT5: 1.4 | AU5: 15 | AV5: 21 | AW5: 10 | AX5: 160
A6: 135 | B6: 1 | C6: 0 | D6: 21.8 | E6: 21.8 | F6: 21.9 | G6: 21.9 | H6: 21.8 | I6: 21.8 | J6: 21.8 | K6: 21.9 | L6: 21.2 | M6: 21.9 | N6: 21.8 | O6: 30.4 | P6: 30.7 | Q6: 28.4 | R6: 28.4 | S6: 17 | T6: 0 | U6: 29.1 | V6: 29.5 | W6: 28.3 | X6: 22.7 | Y6: 22.8 | Z6: 21.8 | AA6: 21.9 | AB6: 21.8 | AC6: 21.9 | AD6: 21.9 | AE6: 28.4 | AF6: 22.7 | AG6: 29.3 | AH6: 30.7 | AI6: 0.5 | AJ6: 0.9 | AK6: 9.2 | AL6: 6.8 | AM6: 1106.9 | AN6: 692.9 | AO6: 5.6 | AP6: 5.6 | AQ6: 0 | AR6: 9.9 | AS6: 5.8 | AT6: 1.3 | AU6: 15 | AV6: 21 | AW6: 10 | AX6: 320
A7: 135 | B7: 1 | C7: 0 | D7: 21.8 | E7: 21.8 | F7: 21.9 | G7: 21.9 | H7: 21.8 | I7: 21.8 | J7: 21.8 | K7: 21.9 | L7: 21.2 | M7: 21.9 | N7: 21.8 | O7: 30.6 | P7: 30.9 | Q7: 28.5 | R7: 28.5 | S7: 17 | T7: 0 | U7: 29.2 | V7: 29.7 | W7: 28.5 | X7: 22.7 | Y7: 22.7 | Z7: 21.8 | AA7: 21.9 | AB7: 21.8 | AC7: 21.9 | AD7: 21.9 | AE7: 28.5 | AF7: 22.7 | AG7: 29.5 | AH7: 30.7 | AI7: 0.5 | AJ7: 0.9 | AK7: 9.2 | AL7: 6.8 | AM7: 1106.9 | AN7: 692.9 | AO7: 5.6 | AP7: 5.6 | AQ7: 0 | AR7: 9.9 | AS7: 5.8 | AT7: 1.3 | AU7: 15 | AV7: 22 | AW7: 10 | AX7: 320
A8: 135 | B8: 1 | C8: 0 | D8: 21.8 | E8: 21.8 | F8: 21.9 | G8: 21.9 | H8: 21.8 | I8: 21.8 | J8: 21.8 | K8: 21.9 | L8: 21.2 | M8: 21.9 | N8: 21.8 | O8: 30.6 | P8: 30.9 | Q8: 28.5 | R8: 28.5 | S8: 17 | T8: 0 | U8: 29.2 | V8: 29.7 | W8: 28.5 | X8: 22.7 | Y8: 22.7 | Z8: 21.8 | AA8: 21.9 | AB8: 21.8 | AC8: 21.9 | AD8: 21.9 | AE8: 28.5 | AF8: 22.7 | AG8: 29.5 | AH8: 30.7 | AI8: 0.5 | AJ8: 0.9 | AK8: 9.2 | AL8: 6.8 | AM8: 1106.9 | AN8: 692.9 | AO8: 5.6 | AP8: 5.6 | AQ8: 0 | AR8: 9.9 | AS8: 5.8 | AT8: 1.3 | AU8: 15 | AV8: 22 | AW8: 10 | AX8: 320
A9: 195 | B9: 1 | C9: 0 | D9: 22.2 | E9: 22.3 | F9: 22.4 | G9: 22.3 | H9: 22.2 | I9: 22.2 | J9: 22.3 | K9: 22.4 | L9: 21.5 | M9: 22.1 | N9: 22 | O9: 34.9 | P9: 35.4 | Q9: 32.8 | R9: 32.8 | S9: 14.5 | T9: 0 | U9: 32.9 | V9: 33.4 | W9: 31.7 | X9: 23.2 | Y9: 23.3 | Z9: 22.2 | AA9: 22.3 | AB9: 22.2 | AC9: 22.3 | AD9: 22.1 | AE9: 32.8 | AF9: 23.3 | AG9: 33.1 | AH9: 35.1 | AI9: 0.6 | AJ9: 1.4 | AK9: 12.8 | AL9: 9.9 | AM9: 1384.3 | AN9: 833.8 | AO9: 5.6 | AP9: 5.6 | AQ9: 0 | AR9: 9.9 | AS9: 5.8 | AT9: 1.3 | AU9: 15 | AV9: 22 | AW9: 25 | AX9: 480
A10: 195 | B10: 1 | C10: 0 | D10: 22.2 | E10: 22.3 | F10: 22.4 | G10: 22.3 | H10: 22.2 | I10: 22.2 | J10: 22.3 | K10: 22.4 | L10: 21.5 | M10: 22.1 | N10: 22 | O10: 34.9 | P10: 35.4 | Q10: 32.8 | R10: 32.8 | S10: 14.6 | T10: 0 | U10: 32.9 | V10: 33.4 | W10: 31.7 | X10: 23.2 | Y10: 23.3 | Z10: 22.2 | AA10: 22.3 | AB10: 22.2 | AC10: 22.3 | AD10: 22.1 | AE10: 32.8 | AF10: 23.3 | AG10: 33.1 | AH10: 35.1 | AI10: 0.6 | AJ10: 1.4 | AK10: 12.8 | AL10: 9.9 | AM10: 1385.8 | AN10: 833.8 | AO10: 5.6 | AP10: 5.6 | AQ10: 0 | AR10: 9.9 | AS10: 5.8 | AT10: 1.3 | AU10: 15 | AV10: 22 | AW10: 25 | AX10: 480
A11: 195 | B11: 1 | C11: 0 | D11: 22.2 | E11: 22.3 | F11: 22.4 | G11: 22.3 | H11: 22.2 | I11: 22.2 | J11: 22.3 | K11: 22.4 | L11: 21.5 | M11: 22.1 | N11: 22 | O11: 34.9 | P11: 35.4 | Q11: 32.8 | R11: 32.8 | S11: 14.6 | T11: 0 | U11: 32.9 | V11: 33.4 | W11: 31.7 | X11: 23.2 | Y11: 23.3 | Z11: 22.2 | AA11: 22.3 | AB11: 22.2 | AC11: 22.3 | AD11: 22.1 | AE11: 32.8 | AF11: 23.3 | AG11: 33.1 | AH11: 35.1 | AI11: 0.6 | AJ11: 1.4 | AK11: 12.8 | AL11: 9.9 | AM11: 1385.8 | AN11: 833.8 | AO11: 5.6 | AP11: 5.6 | AQ11: 0 | AR11: 9.9 | AS11: 5.8 | AT11: 1.3 | AU11: 15 | AV11: 23 | AW11: 25 | AX11: 480
A12: 255 | B12: 1 | C12: 0 | D12: 23 | E12: 23.1 | F12: 23.2 | G12: 23.1 | H12: 23 | I12: 23 | J12: 23.1 | K12: 23.2 | L12: 21.9 | M12: 22.3 | N12: 22.3 | O12: 34.6 | P12: 35.5 | Q12: 32.4 | R12: 32.5 | S12: 13.4 | T12: 0 | U12: 32.8 | V12: 33.2 | W12: 31.7 | X12: 23.2 | Y12: 23.3 | Z12: 23 | AA12: 23.1 | AB12: 23 | AC12: 23.1 | AD12: 22.3 | AE12: 32.5 | AF12: 23.3 | AG12: 33 | AH12: 35 | AI12: 0.4 | AJ12: 1.3 | AK12: 12.7 | AL12: 9.7 | AM12: 1390.1 | AN12: 884.1 | AO12: 5.6 | AP12: 5.6 | AQ12: 0 | AR12: 9.9 | AS12: 5.8 | AT12: 1.4 | AU12: 15 | AV12: 23 | AW12: 33 | AX12: 560
A13: 255 | B13: 1 | C13: 0 | D13: 23 | E13: 23.1 | F13: 23.2 | G13: 23.1 | H13: 23 | I13: 23 | J13: 23.1 | K13: 23.2 | L13: 21.9 | M13: 22.3 | N13: 22.3 | O13: 34.6 | P13: 35.5 | Q13: 32.4 | R13: 32.5 | S13: 13.4 | T13: 0 | U13: 32.8 | V13: 33.2 | W13: 31.7 | X13: 23.2 | Y13: 23.3 | Z13: 23 | AA13: 23.1 | AB13: 23 | AC13: 23.1 | AD13: 22.3 | AE13: 32.5 | AF13: 23.3 | AG13: 33 | AH13: 35 | AI13: 0.4 | AJ13: 1.3 | AK13: 12.7 | AL13: 9.7 | AM13: 1390.1 | AN13: 884.1 | AO13: 5.6 | AP13: 5.6 | AQ13: 0 | AR13: 9.9 | AS13: 5.8 | AT13: 1.4 | AU13: 15 | AV13: 23 | AW13: 33 | AX13: 560
... A29: 525 | B29: 1 | C29: 0 | D29: 25.2 | E29: 25.2 | F29: 25.3 | G29: 25.3 | H29: 25.2 | I29: 25.2 | J29: 25.2 | K29: 25.3 | L29: 23.9 | M29: 22.4 | N29: 22.4 | O29: 30.6 | P29: 30.6 | Q29: 28.6 | R29: 28.7 | S29: 17.4 | T29: 0 | U29: 29.4 | V29: 29.8 | W29: 28.6 | X29: 23.2 | Y29: 23.3 | Z29: 25.2 | AA29: 25.3 | AB29: 25.2 | AC29: 25.3 | AD29: 22.4 | AE29: 28.6 | AF29: 23.2 | AG29: 29.6 | AH29: 30.6 | AI29: 0.1 | AJ29: 1 | AK29: 8.8 | AL29: 6.4 | AM29: 1111.2 | AN29: 678.5 | AO29: 5.6 | AP29: 5.6 | AQ29: 0 | AR29: 9.9 | AS29: 5.7 | AT29: 1.4 | AU29: 15 | AV29: 27 | AW29: 0 | AX29: 160

Sheet max
A1: Time | B1: Status (0-off 1-on) | C1: Group (0-standalone 1-Group lead 2-Group follow) | D1: TT01 | E1: TT02 | F1: TT31 | G1: TT41 | H1: TT61 | I1: TT62 | J1: TT51 | K1: TT52 | L1: TT45 | M1: PT01 | N1: PT02 | O1: PT31 | P1: PT41 | Q1: PT32 | R1: PT42 | S1: PT21 | T1: PT11 | U1: PT51 | V1: PT52 | W1: PT53 | X1: PT61 | Y1: PT62 | Z1: TT01/TT02 | AA1: TT31/TT41 | AB1: TT61/TT62 | AC1: TT51/TT52 | AD1: PT01/PT02 | AE1: PT32/PT42 | AF1: PT61/PT62 | AG1: PT51/PT52 | AH1: Pump 31 Filter DP | AI1: Pump 41 Filter DP | AJ1: Primary Filter 53 DP | AK1: Secondary DP (Supply - Return) | AL1: Primary DP (Supply - Return) | AM1: FT01 | AN1: FT61 | AO1: P31 Speed % | AP1: P41 Speed % | AQ1: FCV61 Actual Flow% | AR1: FCV61 Actual Open% | AS1: Air Humidity | AT1: Air Temperature | AU1: Program version | AV1: Secondary Temperature Setpoint | AW1: Secondary DP Setpoint | AX1: Secondary Flow Setpoint
A2: 15 | B2: 1 | C2: 0 | D2: 42.4 | E2: 42.6 | F2: 42.5 | G2: 42.4 | H2: 42.4 | I2: 42.6 | J2: 42.4 | K2: 42.5 | L2: 40.9 | M2: 28.2 | N2: 28.2 | O2: 47.3 | P2: 47.3 | Q2: 44.8 | R2: 43.7 | S2: 24.4 | T2: 6553.5 | U2: 44.2 | V2: 44.2 | W2: 42 | X2: 6517.4 | Y2: 29.6 | Z2: 42.5 | AA2: 42.4 | AB2: 42.5 | AC2: 42.4 | AD2: 28.2 | AE2: 44.2 | AF2: 29.8 | AG2: 44.2 | AH2: 47.3 | AI2: 3.7 | AJ2: 2.6 | AK2: 6553.5 | AL2: 6553.5 | AM2: 2343.1 | AN2: 6510.5 | AO2: 9.4 | AP2: 9.4 | AQ2: 10 | AR2: 6551.2 | AS2: 49.3 | AT2: 6553 | AU2: 15 | AV2: 40 | AW2: 5 | AX2: 430
A3: 75 | B3: 1 | C3: 0 | D3: 42.6 | E3: 42.8 | F3: 42.6 | G3: 42.6 | H3: 42.6 | I3: 42.7 | J3: 42.6 | K3: 42.7 | L3: 41.1 | M3: 27.7 | N3: 27.7 | O3: 40.6 | P3: 41 | Q3: 38.7 | R3: 38.3 | S3: 22.3 | T3: 6553.5 | U3: 39.4 | V3: 39.1 | W3: 37.3 | X3: 6517.4 | Y3: 29 | Z3: 42.7 | AA3: 42.6 | AB3: 42.6 | AC3: 42.6 | AD3: 27.7 | AE3: 38.5 | AF3: 29.1 | AG3: 39.2 | AH3: 40.8 | AI3: 3.2 | AJ3: 2.3 | AK3: 14 | AL3: 10.8 | AM3: 2343.1 | AN3: 6510.5 | AO3: 7.1 | AP3: 7.1 | AQ3: 10 | AR3: 6551.2 | AS3: 49.4 | AT3: 6553 | AU3: 15 | AV3: 21 | AW3: 5 | AX3: 160
A4: 75 | B4: 1 | C4: 0 | D4: 42.6 | E4: 42.8 | F4: 42.6 | G4: 42.6 | H4: 42.6 | I4: 42.7 | J4: 42.6 | K4: 42.7 | L4: 41.1 | M4: 27.7 | N4: 27.7 | O4: 40.6 | P4: 41 | Q4: 38.7 | R4: 38.3 | S4: 22.3 | T4: 6553.5 | U4: 39.4 | V4: 39.1 | W4: 37.3 | X4: 6517.4 | Y4: 29 | Z4: 42.7 | AA4: 42.6 | AB4: 42.6 | AC4: 42.6 | AD4: 27.7 | AE4: 38.5 | AF4: 29.1 | AG4: 39.2 | AH4: 40.8 | AI4: 3.2 | AJ4: 2.3 | AK4: 14 | AL4: 10.8 | AM4: 2343.1 | AN4: 6510.5 | AO4: 7.1 | AP4: 7.1 | AQ4: 10 | AR4: 6551.2 | AS4: 49.4 | AT4: 6553 | AU4: 15 | AV4: 21 | AW4: 5 | AX4: 160
A5: 75 | B5: 1 | C5: 0 | D5: 42.6 | E5: 42.8 | F5: 42.6 | G5: 42.6 | H5: 42.6 | I5: 42.7 | J5: 42.6 | K5: 42.7 | L5: 41.1 | M5: 27.8 | N5: 27.7 | O5: 40.6 | P5: 41 | Q5: 38.7 | R5: 38.3 | S5: 22.2 | T5: 6553.5 | U5: 39.3 | V5: 39 | W5: 37.3 | X5: 6517.4 | Y5: 29 | Z5: 42.7 | AA5: 42.6 | AB5: 42.6 | AC5: 42.6 | AD5: 27.8 | AE5: 38.5 | AF5: 29.1 | AG5: 39.2 | AH5: 40.8 | AI5: 3.2 | AJ5: 2.3 | AK5: 14 | AL5: 10.8 | AM5: 2343.1 | AN5: 6510.5 | AO5: 7.1 | AP5: 7.1 | AQ5: 10 | AR5: 6551.2 | AS5: 49.4 | AT5: 6553 | AU5: 15 | AV5: 21 | AW5: 10 | AX5: 160
A6: 135 | B6: 1 | C6: 0 | D6: 42.8 | E6: 42.9 | F6: 42.8 | G6: 42.8 | H6: 42.7 | I6: 42.9 | J6: 42.8 | K6: 42.8 | L6: 41.2 | M6: 27.8 | N6: 27.7 | O6: 40.6 | P6: 41 | Q6: 38.6 | R6: 38.3 | S6: 22.3 | T6: 6553.5 | U6: 39.3 | V6: 39.1 | W6: 37.2 | X6: 6517.4 | Y6: 28.9 | Z6: 42.8 | AA6: 42.8 | AB6: 42.8 | AC6: 42.8 | AD6: 27.7 | AE6: 38.4 | AF6: 29.1 | AG6: 39.2 | AH6: 40.8 | AI6: 3.1 | AJ6: 2.2 | AK6: 14 | AL6: 10.8 | AM6: 2343.1 | AN6: 6510.5 | AO6: 8.2 | AP6: 8.2 | AQ6: 10 | AR6: 6551.2 | AS6: 49.4 | AT6: 6552.8 | AU6: 15 | AV6: 21 | AW6: 10 | AX6: 320
A7: 135 | B7: 1 | C7: 0 | D7: 42.8 | E7: 42.9 | F7: 42.8 | G7: 42.8 | H7: 42.7 | I7: 42.9 | J7: 42.8 | K7: 42.8 | L7: 41.2 | M7: 27.8 | N7: 27.7 | O7: 40.6 | P7: 41 | Q7: 38.6 | R7: 38.3 | S7: 22.3 | T7: 6553.5 | U7: 39.3 | V7: 39.1 | W7: 37.2 | X7: 6517.4 | Y7: 28.9 | Z7: 42.8 | AA7: 42.8 | AB7: 42.8 | AC7: 42.8 | AD7: 27.7 | AE7: 38.4 | AF7: 29.1 | AG7: 39.2 | AH7: 40.8 | AI7: 3.1 | AJ7: 2.2 | AK7: 14 | AL7: 10.8 | AM7: 2343.1 | AN7: 6510.5 | AO7: 8.2 | AP7: 8.2 | AQ7: 10 | AR7: 6551.2 | AS7: 49.4 | AT7: 6552.8 | AU7: 15 | AV7: 22 | AW7: 10 | AX7: 320
A8: 135 | B8: 1 | C8: 0 | D8: 42.8 | E8: 42.9 | F8: 42.8 | G8: 42.8 | H8: 42.7 | I8: 42.9 | J8: 42.8 | K8: 42.8 | L8: 41.2 | M8: 27.8 | N8: 27.7 | O8: 40.6 | P8: 41 | Q8: 38.6 | R8: 38.3 | S8: 22.3 | T8: 6553.5 | U8: 39.3 | V8: 39.1 | W8: 37.2 | X8: 6517.4 | Y8: 28.9 | Z8: 42.8 | AA8: 42.8 | AB8: 42.8 | AC8: 42.8 | AD8: 27.7 | AE8: 38.4 | AF8: 29.1 | AG8: 39.2 | AH8: 40.8 | AI8: 3.1 | AJ8: 2.2 | AK8: 14 | AL8: 10.8 | AM8: 2343.1 | AN8: 6510.5 | AO8: 8.2 | AP8: 8.2 | AQ8: 10 | AR8: 6551.2 | AS8: 49.4 | AT8: 6552.8 | AU8: 15 | AV8: 22 | AW8: 25 | AX8: 320
A9: 195 | B9: 1 | C9: 0 | D9: 43.1 | E9: 43.3 | F9: 43.2 | G9: 43.2 | H9: 43.1 | I9: 43.3 | J9: 43.2 | K9: 43.2 | L9: 41.5 | M9: 29.6 | N9: 29.6 | O9: 55.3 | P9: 55.7 | Q9: 51.6 | R9: 51.5 | S9: 20.2 | T9: 6553.5 | U9: 51.3 | V9: 51.1 | W9: 48.2 | X9: 6517.4 | Y9: 31.9 | Z9: 43.2 | AA9: 43.2 | AB9: 43.2 | AC9: 43.2 | AD9: 29.6 | AE9: 51.5 | AF9: 32.2 | AG9: 51.2 | AH9: 55.5 | AI9: 4.4 | AJ9: 3.3 | AK9: 25.3 | AL9: 20 | AM9: 2343.1 | AN9: 6510.5 | AO9: 9.6 | AP9: 10.1 | AQ9: 10 | AR9: 6551.2 | AS9: 49.4 | AT9: 6552.8 | AU9: 15 | AV9: 22 | AW9: 25 | AX9: 480
A10: 195 | B10: 1 | C10: 0 | D10: 43.1 | E10: 43.3 | F10: 43.2 | G10: 43.2 | H10: 43.1 | I10: 43.3 | J10: 43.2 | K10: 43.2 | L10: 41.5 | M10: 29.6 | N10: 29.6 | O10: 55.3 | P10: 55.7 | Q10: 51.6 | R10: 51.5 | S10: 20.2 | T10: 6553.5 | U10: 51.3 | V10: 51.1 | W10: 48.2 | X10: 6517.4 | Y10: 31.9 | Z10: 43.2 | AA10: 43.2 | AB10: 43.2 | AC10: 43.2 | AD10: 29.6 | AE10: 51.5 | AF10: 32.2 | AG10: 51.2 | AH10: 55.5 | AI10: 4.4 | AJ10: 3.3 | AK10: 25.2 | AL10: 20 | AM10: 2343.1 | AN10: 6510.5 | AO10: 9.6 | AP10: 10.1 | AQ10: 10 | AR10: 6551.2 | AS10: 49.4 | AT10: 6552.8 | AU10: 15 | AV10: 23 | AW10: 25 | AX10: 480
